Workbook

Sheet Sheet1
A1: 동기부여 | B1: -10 | D1: 스탯 | E1: 재능 | F1: 순위 | H1: 직업 | I1: 재능 | J1: 순위
A2: 창의력 | B2: 4 | D2: 법 | E2: =VLOOKUP(D2,Sheet2!$A$2:$H$109,8,0) -> -16.666667 | F2: =RANK(E2,$E$2:$E$37) -> 27 | H2: 소방관 | I2: =VLOOKUP(H2,Sheet2!$M:$S,7,0) -> 47.099129 | J2: =RANK(I2,$I$2:$I$68) -> 1
A3: 집중력 | B3: -73 | D3: 미술 | E3: =VLOOKUP(D3,Sheet2!$A$2:$H$109,8,0) -> -22.185185 | F3: =RANK(E3,$E$2:$E$37) -> 32 | H3: 격투기 선수 | I3: =VLOOKUP(H3,Sheet2!$M:$S,7,0) -> 40.911195 | J3: =RANK(I3,$I$2:$I$68) -> 2
A4: 체격 | B4: 26 | D4: 예술 | E4: =VLOOKUP(D4,Sheet2!$A$2:$H$109,8,0) -> -17.608696 | F4: =RANK(E4,$E$2:$E$37) -> 28 | H4: 외교관 | I4: =VLOOKUP(H4,Sheet2!$M:$S,7,0) -> 39.571766 | J4: =RANK(I4,$I$2:$I$68) -> 3
A5: 키 | D5: 요리실력 | E5: =VLOOKUP(D5,Sheet2!$A$2:$H$109,8,0) -> 37.133333 | F5: =RANK(E5,$E$2:$E$37) -> 12 | H5: 교수-소방안전학과 | I5: =VLOOKUP(H5,Sheet2!$M:$S,7,0) -> 39.263354 | J5: =RANK(I5,$I$2:$I$68) -> 4
A6: 얼굴 | B6: 154 | D6: 경찰지식 | E6: =VLOOKUP(D6,Sheet2!$A$2:$H$109,8,0) -> 36.242424 | F6: =RANK(E6,$E$2:$E$37) -> 14 | H6: 공무원-5급 | I6: =VLOOKUP(H6,Sheet2!$M:$S,7,0) -> 38.866057 | J6: =RANK(I6,$I$2:$I$68) -> 5
A7: 기억력 | B7: -24 | D7: 음악 | E7: =VLOOKUP(D7,Sheet2!$A$2:$H$109,8,0) -> -0.71428571 | F7: =RANK(E7,$E$2:$E$37) -> 23 | H7: 공무원-7급 | I7: =VLOOKUP(H7,Sheet2!$M:$S,7,0) -> 38.300956 | J7: =RANK(I7,$I$2:$I$68) -> 6
A8: 언어 능력 | B8: 156 | D8: 창의력 | E8: =VLOOKUP(D8,Sheet2!$A$2:$H$109,8,0) -> -2.1818182 | F8: =RANK(E8,$E$2:$E$37) -> 24 | H8: 군인 | I8: =VLOOKUP(H8,Sheet2!$M:$S,7,0) -> 37.828399 | J8: =RANK(I8,$I$2:$I$68) -> 7
A9: 논리력 | B9: 27 | D9: 디자인 | E9: =VLOOKUP(D9,Sheet2!$A$2:$H$109,8,0) -> -4.3181818 | F9: =RANK(E9,$E$2:$E$37) -> 25 | H9: 쉐프 | I9: =VLOOKUP(H9,Sheet2!$M:$S,7,0) -> 37.577068 | J9: =RANK(I9,$I$2:$I$68) -> 8
A10: 사교성 | B10: 12 | D10: 군사지식 | E10: =VLOOKUP(D10,Sheet2!$A$2:$H$109,8,0) -> 32.777778 | F10: =RANK(E10,$E$2:$E$37) -> 15 | H10: 농부 | I10: =VLOOKUP(H10,Sheet2!$M:$S,7,0) -> 37.420259 | J10: =RANK(I10,$I$2:$I$68) -> 9
A11: 리더십 | B11: 26 | D11: 연기력 | E11: =VLOOKUP(D11,Sheet2!$A$2:$H$109,8,0) -> 27.076923 | F11: =RANK(E11,$E$2:$E$37) -> 18 | H11: 공무원-9급 | I11: =VLOOKUP(H11,Sheet2!$M:$S,7,0) -> 37.213251 | J11: =RANK(I11,$I$2:$I$68) -> 10
A12: 회복력 | B12: 82 | D12: 예능감각 | E12: =VLOOKUP(D12,Sheet2!$A$2:$H$109,8,0) -> 43.096774 | F12: =RANK(E12,$E$2:$E$37) -> 8 | H12: 경찰 | I12: =VLOOKUP(H12,Sheet2!$M:$S,7,0) -> 36.837506 | J12: =RANK(I12,$I$2:$I$68) -> 11
A13: 건강 | B13: 166 | D13: 일하는 기술 | E13: =VLOOKUP(D13,Sheet2!$A$2:$H$109,8,0) -> 14.034483 | F13: =RANK(E13,$E$2:$E$37) -> 22 | H13: 교수-방송연예학과 | I13: =VLOOKUP(H13,Sheet2!$M:$S,7,0) -> 33.897696 | J13: =RANK(I13,$I$2:$I$68) -> 12
A14: 정신력 | B14: -13 | D14: 사무 능력 | E14: =VLOOKUP(D14,Sheet2!$A$2:$H$109,8,0) -> -24.482759 | F14: =RANK(E14,$E$2:$E$37) -> 35 | H14: 교수-경영학과 | I14: =VLOOKUP(H14,Sheet2!$M:$S,7,0) -> 32.203313 | J14: =RANK(I14,$I$2:$I$68) -> 13
A15: 지구력 | B15: -40 | D15: 고급 외국어 | E15: =VLOOKUP(D15,Sheet2!$A$2:$H$109,8,0) -> 22.424658 | F15: =RANK(E15,$E$2:$E$37) -> 20 | H15: 보디빌더 | I15: =VLOOKUP(H15,Sheet2!$M:$S,7,0) -> 31.506356 | J15: =RANK(I15,$I$2:$I$68) -> 14
D16: 경영 | E16: =VLOOKUP(D16,Sheet2!$A$2:$H$109,8,0) -> 40.724638 | F16: =RANK(E16,$E$2:$E$37) -> 10 | H16: 교수-행정학과 | I16: =VLOOKUP(H16,Sheet2!$M:$S,7,0) -> 31.209524 | J16: =RANK(I16,$I$2:$I$68) -> 15
D17: 노가다 기술 | E17: =VLOOKUP(D17,Sheet2!$A$2:$H$109,8,0) -> -30.625 | F17: =RANK(E17,$E$2:$E$37) -> 36 | H17: 연구자-소방안전학과 | I17: =VLOOKUP(H17,Sheet2!$M:$S,7,0) -> 30.754348 | J17: =RANK(I17,$I$2:$I$68) -> 16
D18: 정치 | E18: =VLOOKUP(D18,Sheet2!$A$2:$H$109,8,0) -> 36.338028 | F18: =RANK(E18,$E$2:$E$37) -> 13 | H18: 교수-조리학과 | I18: =VLOOKUP(H18,Sheet2!$M:$S,7,0) -> 29.638095 | J18: =RANK(I18,$I$2:$I$68) -> 17
D19: 공공력 | E19: =VLOOKUP(D19,Sheet2!$A$2:$H$109,8,0) -> 39.333333 | F19: =RANK(E19,$E$2:$E$37) -> 11 | H19: 육상 선수 | I19: =VLOOKUP(H19,Sheet2!$M:$S,7,0) -> 29.372087 | J19: =RANK(I19,$I$2:$I$68) -> 18
D20: 격투 | E20: =VLOOKUP(D20,Sheet2!$A$2:$H$109,8,0) -> 47.291139 | F20: =RANK(E20,$E$2:$E$37) -> 4 | H20: 교수-정치외교학과 | I20: =VLOOKUP(H20,Sheet2!$M:$S,7,0) -> 29.07002 | J20: =RANK(I20,$I$2:$I$68) -> 19
D21: 외국어 | E21: =VLOOKUP(D21,Sheet2!$A$2:$H$109,8,0) -> 45.04 | F21: =RANK(E21,$E$2:$E$37) -> 7 | H21: 교수-경찰학과 | I21: =VLOOKUP(H21,Sheet2!$M:$S,7,0) -> 29.001732 | J21: =RANK(I21,$I$2:$I$68) -> 20
D22: 근력 | E22: =VLOOKUP(D22,Sheet2!$A$2:$H$109,8,0) -> 32 | F22: =RANK(E22,$E$2:$E$37) -> 16 | H22: 연구자-방송연예학과 | I22: =VLOOKUP(H22,Sheet2!$M:$S,7,0) -> 26.998387 | J22: =RANK(I22,$I$2:$I$68) -> 21
D23: 필력 | E23: =VLOOKUP(D23,Sheet2!$A$2:$H$109,8,0) -> 24.492308 | F23: =RANK(E23,$E$2:$E$37) -> 19 | H23: 교수-군사학과 | I23: =VLOOKUP(H23,Sheet2!$M:$S,7,0) -> 26.526984 | J23: =RANK(I23,$I$2:$I$68) -> 22
D24: 수리 능력 | E24: =VLOOKUP(D24,Sheet2!$A$2:$H$109,8,0) -> -18.535714 | F24: =RANK(E24,$E$2:$E$37) -> 29 | H24: 정치인 | I24: =VLOOKUP(H24,Sheet2!$M:$S,7,0) -> 26.357713 | J24: =RANK(I24,$I$2:$I$68) -> 23
D25: 의학 | E25: =VLOOKUP(D25,Sheet2!$A$2:$H$109,8,0) -> -24.333333 | F25: =RANK(E25,$E$2:$E$37) -> 34 | H25: 연구자-경영학과 | I25: =VLOOKUP(H25,Sheet2!$M:$S,7,0) -> 25.812319 | J25: =RANK(I25,$I$2:$I$68) -> 24
D26: 컴퓨터과학 | E26: =VLOOKUP(D26,Sheet2!$A$2:$H$109,8,0) -> -19.54717 | F26: =RANK(E26,$E$2:$E$37) -> 31 | H26: 교수-체육대학 | I26: =VLOOKUP(H26,Sheet2!$M:$S,7,0) -> 25.632446 | J26: =RANK(I26,$I$2:$I$68) -> 25
D27: 금융 | E27: =VLOOKUP(D27,Sheet2!$A$2:$H$109,8,0) -> -22.372549 | F27: =RANK(E27,$E$2:$E$37) -> 33 | H27: 연구자-행정학과 | I27: =VLOOKUP(H27,Sheet2!$M:$S,7,0) -> 25.116667 | J27: =RANK(I27,$I$2:$I$68) -> 26
... D37: 체력 | E37: =VLOOKUP(D37,Sheet2!$A$2:$H$109,8,0) -> 45.125 | F37: =RANK(E37,$E$2:$E$37) -> 6 | H37: 교수-외교학과 | I37: =VLOOKUP(H37,Sheet2!$M:$S,7,0) -> 19.131898 | J37: =RANK(I37,$I$2:$I$68) -> 36
H38: 연구자-국어국문학과 | I38: =VLOOKUP(H38,Sheet2!$M:$S,7,0) -> 17.696154 | J38: =RANK(I38,$I$2:$I$68) -> 37
H39: 연구자-외교학과 | I39: =VLOOKUP(H39,Sheet2!$M:$S,7,0) -> 16.662329 | J39: =RANK(I39,$I$2:$I$68) -> 38
H40: 배우 | I40: =VLOOKUP(H40,Sheet2!$M:$S,7,0) -> 15.7699 | J40: =RANK(I40,$I$2:$I$68) -> 39
H41: 생산직 | I41: =VLOOKUP(H41,Sheet2!$M:$S,7,0) -> 14.954741 | J41: =RANK(I41,$I$2:$I$68) -> 40
H42: 기술자 | I42: =VLOOKUP(H42,Sheet2!$M:$S,7,0) -> 14.954741 | J42: =RANK(I42,$I$2:$I$68) -> 40
H43: 교수-산업공학과 | I43: =VLOOKUP(H43,Sheet2!$M:$S,7,0) -> 13.138916 | J43: =RANK(I43,$I$2:$I$68) -> 42
H44: 연구자-산업공학과 | I44: =VLOOKUP(H44,Sheet2!$M:$S,7,0) -> 12.467241 | J44: =RANK(I44,$I$2:$I$68) -> 43
H45: 작가 | I45: =VLOOKUP(H45,Sheet2!$M:$S,7,0) -> 11.155245 | J45: =RANK(I45,$I$2:$I$68) -> 44
H46: 가수 | I46: =VLOOKUP(H46,Sheet2!$M:$S,7,0) -> 10.824167 | J46: =RANK(I46,$I$2:$I$68) -> 45
H47: 직장인 | I47: =VLOOKUP(H47,Sheet2!$M:$S,7,0) -> 10.664276 | J47: =RANK(I47,$I$2:$I$68) -> 46
H48: 검사 | I48: =VLOOKUP(H48,Sheet2!$M:$S,7,0) -> 8.6435084 | J48: =RANK(I48,$I$2:$I$68) -> 47
H49: 연구자-디자인학과 | I49: =VLOOKUP(H49,Sheet2!$M:$S,7,0) -> 3.2909091 | J49: =RANK(I49,$I$2:$I$68) -> 48
...

Sheet Sheet2
B1: 1 | C1: 2 | D1: 3 | E1: 4 | F1: 5 | G1: 6 | H1: 재능 | N1: 1 | O1: 2 | P1: 3 | Q1: 4 | R1: 5 | S1: 재능
A2: 법 | B2: 동기부여 | C2: 집중력 | D2: 기억력 | E2: 논리력 | H2: =SUMPRODUCT(B3:G3,B4:G4)/SUM(B3:G3) -> -16.666667 | J2: 동기부여 | K2: =COUNTIF(B:G,J2) -> 21 | M2: 일용직노동자 | N2: 체력 | O2: 근력 | P2: 노가다 기술 | Q2: 참을성 | S2: =SUMPRODUCT(N3:R3,N4:R4)/SUM(N3:R3) -> -1.703125
B3: 0.9 | C3: 0.7 | D3: 0.8 | E3: 0.9 | J3: 창의력 | K3: =COUNTIF(B:G,J3) -> 11 | N3: 0.25 | O3: 0.25 | P3: 1 | Q3: 0.5
B4: =IFERROR(VLOOKUP(B2,Sheet1!$A$1:$B$15,2,0),"") -> -10 | C4: =IFERROR(VLOOKUP(C2,Sheet1!$A$1:$B$15,2,0),"") -> -73 | D4: =IFERROR(VLOOKUP(D2,Sheet1!$A$1:$B$15,2,0),"") -> -24 | E4: =IFERROR(VLOOKUP(E2,Sheet1!$A$1:$B$15,2,0),"") -> 27 | F4: =IFERROR(VLOOKUP(F2,Sheet1!$A$1:$B$15,2,0),"") | G4: =IFERROR(VLOOKUP(G2,Sheet1!$A$1:$B$15,2,0),"") | J4: 집중력 | K4: =COUNTIF(B:G,J4) -> 18 | N4: =IFERROR(VLOOKUP(N2,$A$2:$H$109,8,0),"") -> 45.125 | O4: =IFERROR(VLOOKUP(O2,$A$2:$H$109,8,0),"") -> 32 | P4: =IFERROR(VLOOKUP(P2,$A$2:$H$109,8,0),"") -> -30.625 | Q4: =IFERROR(VLOOKUP(Q2,$A$2:$H$109,8,0),"") -> 15.875 | R4: =IFERROR(VLOOKUP(R2,$A$2:$H$109,8,0),"")
A5: 미술 | B5: 동기부여 | C5: 창의력 | D5: 집중력 | E5: 기억력 | H5: =SUMPRODUCT(B6:G6,B7:G7)/SUM(B6:G6) -> -22.185185 | J5: 체격 | K5: =COUNTIF(B:G,J5) -> 6 | M5: 생산직 | N5: 일하는 기술 | O5: 참을성 | S5: =SUMPRODUCT(N6:R6,N7:R7)/SUM(N6:R6) -> 14.954741
B6: 0.8 | C6: 1 | D6: 0.7 | E6: 0.2 | J6: 얼굴 | K6: =COUNTIF(B:G,J6) -> 2 | N6: 1 | O6: 1
B7: =IFERROR(VLOOKUP(B5,Sheet1!$A$1:$B$15,2,0),"") -> -10 | C7: =IFERROR(VLOOKUP(C5,Sheet1!$A$1:$B$15,2,0),"") -> 4 | D7: =IFERROR(VLOOKUP(D5,Sheet1!$A$1:$B$15,2,0),"") -> -73 | E7: =IFERROR(VLOOKUP(E5,Sheet1!$A$1:$B$15,2,0),"") -> -24 | F7: =IFERROR(VLOOKUP(F5,Sheet1!$A$1:$B$15,2,0),"") | G7: =IFERROR(VLOOKUP(G5,Sheet1!$A$1:$B$15,2,0),"") | J7: 기억력 | K7: =COUNTIF(B:G,J7) -> 15 | N7: =IFERROR(VLOOKUP(N5,$A$2:$H$109,8,0),"") -> 14.034483 | O7: =IFERROR(VLOOKUP(O5,$A$2:$H$109,8,0),"") -> 15.875 | P7: =IFERROR(VLOOKUP(P5,$A$2:$H$109,8,0),"") | Q7: =IFERROR(VLOOKUP(Q5,$A$2:$H$109,8,0),"") | R7: =IFERROR(VLOOKUP(R5,$A$2:$H$109,8,0),"")
A8: 예술 | B8: 동기부여 | C8: 창의력 | D8: 집중력 | H8: =SUMPRODUCT(B9:G9,B10:G10)/SUM(B9:G9) -> -17.608696 | J8: 언어 능력 | K8: =COUNTIF(B:G,J8) -> 10 | M8: 기술자 | N8: 일하는 기술 | O8: 참을성 | S8: =SUMPRODUCT(N9:R9,N10:R10)/SUM(N9:R9) -> 14.954741
B9: 0.8 | C9: 1 | D9: 0.5 | J9: 논리력 | K9: =COUNTIF(B:G,J9) -> 13 | N9: 1 | O9: 1
B10: =IFERROR(VLOOKUP(B8,Sheet1!$A$1:$B$15,2,0),"") -> -10 | C10: =IFERROR(VLOOKUP(C8,Sheet1!$A$1:$B$15,2,0),"") -> 4 | D10: =IFERROR(VLOOKUP(D8,Sheet1!$A$1:$B$15,2,0),"") -> -73 | E10: =IFERROR(VLOOKUP(E8,Sheet1!$A$1:$B$15,2,0),"") | F10: =IFERROR(VLOOKUP(F8,Sheet1!$A$1:$B$15,2,0),"") | G10: =IFERROR(VLOOKUP(G8,Sheet1!$A$1:$B$15,2,0),"") | J10: 사교성 | K10: =COUNTIF(B:G,J10) -> 10 | N10: =IFERROR(VLOOKUP(N8,$A$2:$H$109,8,0),"") -> 14.034483 | O10: =IFERROR(VLOOKUP(O8,$A$2:$H$109,8,0),"") -> 15.875 | P10: =IFERROR(VLOOKUP(P8,$A$2:$H$109,8,0),"") | Q10: =IFERROR(VLOOKUP(Q8,$A$2:$H$109,8,0),"") | R10: =IFERROR(VLOOKUP(R8,$A$2:$H$109,8,0),"")
A11: 요리실력 | B11: 동기부여 | C11: 창의력 | D11: 건강 | E11: 지구력 | H11: =SUMPRODUCT(B12:G12,B13:G13)/SUM(B12:G12) -> 37.133333 | J11: 리더십 | K11: =COUNTIF(B:G,J11) -> 5 | M11: 농부 | N11: 농사기술 | O11: 참을성 | S11: =SUMPRODUCT(N12:R12,N13:R13)/SUM(N12:R12) -> 37.420259
B12: 0.8 | C12: 0.5 | D12: 0.9 | E12: 0.8 | J12: 회복력 | K12: =COUNTIF(B:G,J12) -> 4 | N12: 1 | O12: 1
B13: =IFERROR(VLOOKUP(B11,Sheet1!$A$1:$B$15,2,0),"") -> -10 | C13: =IFERROR(VLOOKUP(C11,Sheet1!$A$1:$B$15,2,0),"") -> 4 | D13: =IFERROR(VLOOKUP(D11,Sheet1!$A$1:$B$15,2,0),"") -> 166 | E13: =IFERROR(VLOOKUP(E11,Sheet1!$A$1:$B$15,2,0),"") -> -40 | F13: =IFERROR(VLOOKUP(F11,Sheet1!$A$1:$B$15,2,0),"") | G13: =IFERROR(VLOOKUP(G11,Sheet1!$A$1:$B$15,2,0),"") | J13: 건강 | K13: =COUNTIF(B:G,J13) -> 10 | N13: =IFERROR(VLOOKUP(N11,$A$2:$H$109,8,0),"") -> 58.965517 | O13: =IFERROR(VLOOKUP(O11,$A$2:$H$109,8,0),"") -> 15.875 | P13: =IFERROR(VLOOKUP(P11,$A$2:$H$109,8,0),"") | Q13: =IFERROR(VLOOKUP(Q11,$A$2:$H$109,8,0),"") | R13: =IFERROR(VLOOKUP(R11,$A$2:$H$109,8,0),"")
A14: 경찰지식 | B14: 동기부여 | C14: 체격 | D14: 사교성 | E14: 건강 | F14: 지구력 | H14: =SUMPRODUCT(B15:G15,B16:G16)/SUM(B15:G15) -> 36.242424 | J14: 정신력 | K14: =COUNTIF(B:G,J14) -> 6 | M14: 직장인 | N14: 사무 능력 | O14: 외국어 | P14: 사교성 | Q14: 참을성 | S14: =SUMPRODUCT(N15:R15,N16:R16)/SUM(N15:R15) -> 10.664276
B15: 0.8 | C15: 0.4 | D15: 0.7 | E15: 0.8 | F15: 0.6 | J15: 지구력 | K15: =COUNTIF(B:G,J15) -> 12 | N15: 1 | O15: 0.2 | P15: 0.5 | Q15: 0.7
B16: =IFERROR(VLOOKUP(B14,Sheet1!$A$1:$B$15,2,0),"") -> -10 | C16: =IFERROR(VLOOKUP(C14,Sheet1!$A$1:$B$15,2,0),"") -> 26 | D16: =IFERROR(VLOOKUP(D14,Sheet1!$A$1:$B$15,2,0),"") -> 12 | E16: =IFERROR(VLOOKUP(E14,Sheet1!$A$1:$B$15,2,0),"") -> 166 | F16: =IFERROR(VLOOKUP(F14,Sheet1!$A$1:$B$15,2,0),"") -> -40 | G16: =IFERROR(VLOOKUP(G14,Sheet1!$A$1:$B$15,2,0),"") | N16: =IFERROR(VLOOKUP(N14,$A$2:$H$109,8,0),"") -> -24.482759 | O16: =IFERROR(VLOOKUP(O14,$A$2:$H$109,8,0),"") -> 45.04 | P16: =IFERROR(VLOOKUP(P14,$A$2:$H$109,8,0),"") -> 59.913043 | Q16: =IFERROR(VLOOKUP(Q14,$A$2:$H$109,8,0),"") -> 15.875 | R16: =IFERROR(VLOOKUP(R14,$A$2:$H$109,8,0),"")
A17: 음악 | B17: 동기부여 | C17: 창의력 | D17: 사교성 | E17: 정신력 | H17: =SUMPRODUCT(B18:G18,B19:G19)/SUM(B18:G18) -> -0.71428571 | M17: 보디빌더 | N17: 근력 | O17: 체력 | P17: 참을성 | Q17: 운동 능력 | S17: =SUMPRODUCT(N18:R18,N19:R19)/SUM(N18:R18) -> 31.506356
B18: 0.8 | C18: 1 | D18: 0.6 | E18: 0.4 | N18: 1 | O18: 0.25 | P18: 0.25 | Q18: 0.5
B19: =IFERROR(VLOOKUP(B17,Sheet1!$A$1:$B$15,2,0),"") -> -10 | C19: =IFERROR(VLOOKUP(C17,Sheet1!$A$1:$B$15,2,0),"") -> 4 | D19: =IFERROR(VLOOKUP(D17,Sheet1!$A$1:$B$15,2,0),"") -> 12 | E19: =IFERROR(VLOOKUP(E17,Sheet1!$A$1:$B$15,2,0),"") -> -13 | F19: =IFERROR(VLOOKUP(F17,Sheet1!$A$1:$B$15,2,0),"") | G19: =IFERROR(VLOOKUP(G17,Sheet1!$A$1:$B$15,2,0),"") | N19: =IFERROR(VLOOKUP(N17,$A$2:$H$109,8,0),"") -> 32 | O19: =IFERROR(VLOOKUP(O17,$A$2:$H$109,8,0),"") -> 45.125 | P19: =IFERROR(VLOOKUP(P17,$A$2:$H$109,8,0),"") -> 15.875 | Q19: =IFERROR(VLOOKUP(Q17,$A$2:$H$109,8,0),"") -> 31.525424 | R19: =IFERROR(VLOOKUP(R17,$A$2:$H$109,8,0),"")
A20: 창의력 | B20: 동기부여 | C20: 창의력 | D20: 기억력 | E20: 논리력 | H20: =SUMPRODUCT(B21:G21,B22:G22)/SUM(B21:G21) -> -2.1818182 | M20: 쉐프 | N20: 요리실력 | O20: 사교성 | P20: 참을성 | S20: =SUMPRODUCT(N21:R21,N22:R22)/SUM(N21:R21) -> 37.577068
B21: 0.7 | C21: 1 | D21: 0.3 | E21: 0.2 | N21: 1 | O21: 0.7 | P21: 0.7
B22: =IFERROR(VLOOKUP(B20,Sheet1!$A$1:$B$15,2,0),"") -> -10 | C22: =IFERROR(VLOOKUP(C20,Sheet1!$A$1:$B$15,2,0),"") -> 4 | D22: =IFERROR(VLOOKUP(D20,Sheet1!$A$1:$B$15,2,0),"") -> -24 | E22: =IFERROR(VLOOKUP(E20,Sheet1!$A$1:$B$15,2,0),"") -> 27 | F22: =IFERROR(VLOOKUP(F20,Sheet1!$A$1:$B$15,2,0),"") | G22: =IFERROR(VLOOKUP(G20,Sheet1!$A$1:$B$15,2,0),"") | N22: =IFERROR(VLOOKUP(N20,$A$2:$H$109,8,0),"") -> 37.133333 | O22: =IFERROR(VLOOKUP(O20,$A$2:$H$109,8,0),"") -> 59.913043 | P22: =IFERROR(VLOOKUP(P20,$A$2:$H$109,8,0),"") -> 15.875 | Q22: =IFERROR(VLOOKUP(Q20,$A$2:$H$109,8,0),"") | R22: =IFERROR(VLOOKUP(R20,$A$2:$H$109,8,0),"")
A23: 디자인 | B23: 동기부여 | C23: 창의력 | D23: 정신력 | H23: =SUMPRODUCT(B24:G24,B25:G25)/SUM(B24:G24) -> -4.3181818 | M23: 소방관 | N23: 소방지식 | O23: 체력 | P23: 운동 능력 | S23: =SUMPRODUCT(N24:R24,N25:R25)/SUM(N24:R24) -> 47.099129
B24: 0.7 | C24: 1 | D24: 0.5 | N24: 1 | O24: 0.2 | P24: 0.2
B25: =IFERROR(VLOOKUP(B23,Sheet1!$A$1:$B$15,2,0),"") -> -10 | C25: =IFERROR(VLOOKUP(C23,Sheet1!$A$1:$B$15,2,0),"") -> 4 | D25: =IFERROR(VLOOKUP(D23,Sheet1!$A$1:$B$15,2,0),"") -> -13 | E25: =IFERROR(VLOOKUP(E23,Sheet1!$A$1:$B$15,2,0),"") | F25: =IFERROR(VLOOKUP(F23,Sheet1!$A$1:$B$15,2,0),"") | G25: =IFERROR(VLOOKUP(G23,Sheet1!$A$1:$B$15,2,0),"") | N25: =IFERROR(VLOOKUP(N23,$A$2:$H$109,8,0),"") -> 50.608696 | O25: =IFERROR(VLOOKUP(O23,$A$2:$H$109,8,0),"") -> 45.125 | P25: =IFERROR(VLOOKUP(P23,$A$2:$H$109,8,0),"") -> 31.525424 | Q25: =IFERROR(VLOOKUP(Q23,$A$2:$H$109,8,0),"") | R25: =IFERROR(VLOOKUP(R23,$A$2:$H$109,8,0),"")
A26: 군사지식 | B26: 동기부여 | C26: 집중력 | D26: 건강 | E26: 지구력 | H26: =SUMPRODUCT(B27:G27,B28:G28)/SUM(B27:G27) -> 32.777778 | M26: 경찰 | N26: 경찰지식 | O26: 체력 | P26: 운동 능력 | S26: =SUMPRODUCT(N27:R27,N28:R28)/SUM(N27:R27) -> 36.837506
B27: 0.7 | C27: 0.3 | D27: 0.9 | E27: 0.8 | N27: 1 | O27: 0.2 | P27: 0.2
B28: =IFERROR(VLOOKUP(B26,Sheet1!$A$1:$B$15,2,0),"") -> -10 | C28: =IFERROR(VLOOKUP(C26,Sheet1!$A$1:$B$15,2,0),"") -> -73 | D28: =IFERROR(VLOOKUP(D26,Sheet1!$A$1:$B$15,2,0),"") -> 166 | E28: =IFERROR(VLOOKUP(E26,Sheet1!$A$1:$B$15,2,0),"") -> -40 | F28: =IFERROR(VLOOKUP(F26,Sheet1!$A$1:$B$15,2,0),"") | G28: =IFERROR(VLOOKUP(G26,Sheet1!$A$1:$B$15,2,0),"") | N28: =IFERROR(VLOOKUP(N26,$A$2:$H$109,8,0),"") -> 36.242424 | O28: =IFERROR(VLOOKUP(O26,$A$2:$H$109,8,0),"") -> 45.125 | P28: =IFERROR(VLOOKUP(P26,$A$2:$H$109,8,0),"") -> 31.525424 | Q28: =IFERROR(VLOOKUP(Q26,$A$2:$H$109,8,0),"") | R28: =IFERROR(VLOOKUP(R26,$A$2:$H$109,8,0),"")
A29: 연기력 | B29: 동기부여 | C29: 얼굴 | D29: 사교성 | E29: 리더십 | H29: =SUMPRODUCT(B30:G30,B31:G31)/SUM(B30:G30) -> 27.076923 | M29: 군인 | N29: 군사지식 | O29: 체력 | P29: 운동 능력 | Q29: 리더십 | S29: =SUMPRODUCT(N30:R30,N31:R31)/SUM(N30:R30) -> 37.828399
B30: 0.6 | C30: 0.3 | D30: 1 | E30: 0.7 | N30: 1 | O30: 0.2 | P30: 0.2 | Q30: 0.6
B31: =IFERROR(VLOOKUP(B29,Sheet1!$A$1:$B$15,2,0),"") -> -10 | C31: =IFERROR(VLOOKUP(C29,Sheet1!$A$1:$B$15,2,0),"") -> 154 | D31: =IFERROR(VLOOKUP(D29,Sheet1!$A$1:$B$15,2,0),"") -> 12 | E31: =IFERROR(VLOOKUP(E29,Sheet1!$A$1:$B$15,2,0),"") -> 26 | F31: =IFERROR(VLOOKUP(F29,Sheet1!$A$1:$B$15,2,0),"") | G31: =IFERROR(VLOOKUP(G29,Sheet1!$A$1:$B$15,2,0),"") | N31: =IFERROR(VLOOKUP(N29,$A$2:$H$109,8,0),"") -> 32.777778 | O31: =IFERROR(VLOOKUP(O29,$A$2:$H$109,8,0),"") -> 45.125 | P31: =IFERROR(VLOOKUP(P29,$A$2:$H$109,8,0),"") -> 31.525424 | Q31: =IFERROR(VLOOKUP(Q29,$A$2:$H$109,8,0),"") -> 45.914894 | R31: =IFERROR(VLOOKUP(R29,$A$2:$H$109,8,0),"")
A32: 예능감각 | B32: 동기부여 | C32: 창의력 | D32: 언어 능력 | E32: 사교성 | H32: =SUMPRODUCT(B33:G33,B34:G34)/SUM(B33:G33) -> 43.096774 | M32: 개발자 | N32: 컴퓨터과학 | O32: 논리적 사고 | P32: 수리 능력 | S32: =SUMPRODUCT(N33:R33,N34:R34)/SUM(N33:R33) -> -19.393377
B33: 0.6 | C33: 0.7 | D33: 0.8 | E33: 1 | N33: 1 | O33: 0.6 | P33: 0.1
B34: =IFERROR(VLOOKUP(B32,Sheet1!$A$1:$B$15,2,0),"") -> -10 | C34: =IFERROR(VLOOKUP(C32,Sheet1!$A$1:$B$15,2,0),"") -> 4 | D34: =IFERROR(VLOOKUP(D32,Sheet1!$A$1:$B$15,2,0),"") -> 156 | E34: =IFERROR(VLOOKUP(E32,Sheet1!$A$1:$B$15,2,0),"") -> 12 | F34: =IFERROR(VLOOKUP(F32,Sheet1!$A$1:$B$15,2,0),"") | G34: =IFERROR(VLOOKUP(G32,Sheet1!$A$1:$B$15,2,0),"") | N34: =IFERROR(VLOOKUP(N32,$A$2:$H$109,8,0),"") -> -19.54717 | O34: =IFERROR(VLOOKUP(O32,$A$2:$H$109,8,0),"") -> -19.28 | P34: =IFERROR(VLOOKUP(P32,$A$2:$H$109,8,0),"") -> -18.535714 | Q34: =IFERROR(VLOOKUP(Q32,$A$2:$H$109,8,0),"") | R34: =IFERROR(VLOOKUP(R32,$A$2:$H$109,8,0),"")
A35: 일하는 기술 | B35: 동기부여 | C35: 집중력 | D35: 건강 | E35: 지구력 | H35: =SUMPRODUCT(B36:G36,B37:G37)/SUM(B36:G36) -> 14.034483 | M35: 격투기 선수 | N35: 격투 | O35: 참을성 | P35: 체력 | Q35: 근력 | S35: =SUMPRODUCT(N36:R36,N37:R37)/SUM(N36:R36) -> 40.911195
B36: 0.5 | C36: 0.7 | D36: 0.8 | E36: 0.9 | N36: 1 | O36: 0.25 | P36: 0.5 | Q36: 0.25
B37: =IFERROR(VLOOKUP(B35,Sheet1!$A$1:$B$15,2,0),"") -> -10 | C37: =IFERROR(VLOOKUP(C35,Sheet1!$A$1:$B$15,2,0),"") -> -73 | D37: =IFERROR(VLOOKUP(D35,Sheet1!$A$1:$B$15,2,0),"") -> 166 | E37: =IFERROR(VLOOKUP(E35,Sheet1!$A$1:$B$15,2,0),"") -> -40 | F37: =IFERROR(VLOOKUP(F35,Sheet1!$A$1:$B$15,2,0),"") | G37: =IFERROR(VLOOKUP(G35,Sheet1!$A$1:$B$15,2,0),"") | N37: =IFERROR(VLOOKUP(N35,$A$2:$H$109,8,0),"") -> 47.291139 | O37: =IFERROR(VLOOKUP(O35,$A$2:$H$109,8,0),"") -> 15.875 | P37: =IFERROR(VLOOKUP(P35,$A$2:$H$109,8,0),"") -> 45.125 | Q37: =IFERROR(VLOOKUP(Q35,$A$2:$H$109,8,0),"") -> 32 | R37: =IFERROR(VLOOKUP(R35,$A$2:$H$109,8,0),"")
A38: 사무 능력 | B38: 동기부여 | C38: 집중력 | D38: 기억력 | E38: 논리력 | H38: =SUMPRODUCT(B39:G39,B40:G40)/SUM(B39:G39) -> -24.482759 | M38: 육상 선수 | N38: 운동 능력 | O38: 체력 | P38: 참을성 | Q38: 근력 | S38: =SUMPRODUCT(N39:R39,N40:R40)/SUM(N39:R39) -> 29.372087
B39: 0.5 | C39: 0.9 | D39: 0.8 | E39: 0.7 | N39: 1 | O39: 0.25 | P39: 0.5 | Q39: 0.25
B40: =IFERROR(VLOOKUP(B38,Sheet1!$A$1:$B$15,2,0),"") -> -10 | C40: =IFERROR(VLOOKUP(C38,Sheet1!$A$1:$B$15,2,0),"") -> -73 | D40: =IFERROR(VLOOKUP(D38,Sheet1!$A$1:$B$15,2,0),"") -> -24 | E40: =IFERROR(VLOOKUP(E38,Sheet1!$A$1:$B$15,2,0),"") -> 27 | F40: =IFERROR(VLOOKUP(F38,Sheet1!$A$1:$B$15,2,0),"") | G40: =IFERROR(VLOOKUP(G38,Sheet1!$A$1:$B$15,2,0),"") | N40: =IFERROR(VLOOKUP(N38,$A$2:$H$109,8,0),"") -> 31.525424 | O40: =IFERROR(VLOOKUP(O38,$A$2:$H$109,8,0),"") -> 45.125 | P40: =IFERROR(VLOOKUP(P38,$A$2:$H$109,8,0),"") -> 15.875 | Q40: =IFERROR(VLOOKUP(Q38,$A$2:$H$109,8,0),"") -> 32 | R40: =IFERROR(VLOOKUP(R38,$A$2:$H$109,8,0),"")
...
